<sdf version='1.6'>
  <world name='marsyard2021'>
    <physics name='default_physics' default='0' type='ode'>
      <ode>
        <solver>
          <friction_model>cone_model</friction_model>
          <island_threads>6</island_threads>
          <type>quick</type>
          <iters>50</iters>
          <sor>1.3</sor>
          <use_dynamic_moi_rescaling>0</use_dynamic_moi_rescaling>
        </solver>
        <constraints>
          <cfm>0</cfm>
          <erp>0.2</erp>
          <contact_max_correcting_vel>100</contact_max_correcting_vel>
          <contact_surface_layer>0.001</contact_surface_layer>
        </constraints>
      </ode>
      <max_step_size>0.001</max_step_size>
      <real_time_factor>1</real_time_factor>
      <real_time_update_rate>1000</real_time_update_rate>
    </physics>
    <light name='sun' type='directional'>
      <pose frame=''>0 0 100 0 0.8 0</pose>
      <diffuse>1 1 1 1</diffuse>
      <specular>0.1 0.1 0.1 1</specular>
      <cast_shadows>1</cast_shadows>
      <direction>0 0 -1</direction>
    </light>
    <scene>
      <ambient>0.6 0.6 0.6 1</ambient>
      <sky>
        <clouds>
          <speed>12</speed>
        </clouds>
      </sky>
      <shadows>1</shadows>
      <origin_visual>1</origin_visual>
      <background>0.7 0.7 0.7 1</background>
    </scene>
    <model name='ground_plane'>
      <static>1</static>
      <link name='link'>
        <collision name='collision'>
          <geometry>
            <plane>
              <normal>0 0 1</normal>
              <size>100 100</size>
            </plane>
          </geometry>
          <surface>
            <contact>
              <collide_bitmask>65535</collide_bitmask>
              <ode/>
            </contact>
            <friction>
              <ode>
                <mu>100</mu>
                <mu2>50</mu2>
              </ode>
              <torsional>
                <ode/>
              </torsional>
            </friction>
            <bounce/>
          </surface>
          <max_contacts>10</max_contacts>
        </collision>
        <visual name='visual'>
          <cast_shadows>0</cast_shadows>
          <geometry>
            <plane>
              <normal>0 0 1</normal>
              <size>100 100</size>
            </plane>
          </geometry>
          <material>
            <script>
              <uri>file://media/materials/scripts/gazebo.material</uri>
              <name>Gazebo/Grey</name>
            </script>
          </material>
        </visual>
        <self_collide>0</self_collide>
        <enable_wind>0</enable_wind>
        <kinematic>0</kinematic>
      </link>
    </model>
    <actor name='Lâgari Hasan Çelebi'>
      <link name='cosmonaut'>
        <visual name='visual'>
          <pose frame=''>0 25 0.9 0 -0 1.57</pose>
          <geometry>
            <mesh>
              <scale>1 1 1</scale>
              <uri>/home/baran/rover_simulation_ws/src/Simulations/blender_gazebo/worlds/cosmonaut-dae/cosmonaut.dae</uri>
            </mesh>
          </geometry>
        </visual>
        <self_collide>0</self_collide>
        <enable_wind>0</enable_wind>
      </link>
      <script>
        <loop>1</loop>
        <auto_start>1</auto_start>
        <trajectory id='0' type='square'>
          <waypoint>
            <time>0</time>
            <pose>-1 -1 0 0 -0 0</pose>
          </waypoint>
          <waypoint>
            <time>30</time>
            <pose>20 -1 0 0 -0 0</pose>
          </waypoint>
        </trajectory>
      </script>
    </actor>
    <model name='landmark1'>
      <pose frame=''>3 4 1.42 0 -0 0</pose>
      <static>1</static>
      <link name='landmark'>
        <visual name='pole_visual'>
          <pose frame=''>0 0 0.1 0 -0 0</pose>
          <geometry>
            <cylinder>
              <radius>0.01</radius>
              <length>0.4</length>
            </cylinder>
          </geometry>
          <material>
            <script>
              <name>Gazebo/Wood</name>
              <uri>__default__</uri>
            </script>
          </material>
        </visual>
        <collision name='pole_collision'>
          <pose frame=''>0 0 0.1 0 -0 0</pose>
          <geometry>
            <cylinder>
              <radius>0.01</radius>
              <length>0.4</length>
            </cylinder>
          </geometry>
          <max_contacts>10</max_contacts>
          <surface>
            <contact>
              <ode/>
            </contact>
            <bounce/>
            <friction>
              <torsional>
                <ode/>
              </torsional>
              <ode/>
            </friction>
          </surface>
        </collision>
        <visual name='box_visual'>
          <pose frame=''>0 0 0.31 0 -0 1.0472</pose>
          <geometry>
            <mesh>
              <uri>/home/baran/rover_simulation_ws/src/Simulations/blender_gazebo/sdf/meshes/ERC_Sign.stl</uri>
              <scale>0.0013 0.0013 0.001</scale>
            </mesh>
          </geometry>
          <material>
            <script>
              <name>Gazebo/White</name>
              <uri>__default__</uri>
            </script>
          </material>
        </visual>
        <collision name='box_collision'>
          <pose frame=''>0 0 0.31 0 -0 1.0472</pose>
          <geometry>
            <mesh>
              <uri>/home/baran/rover_simulation_ws/src/Simulations/blender_gazebo/sdf/meshes/ERC_Sign.stl</uri>
              <scale>0.0013 0.0013 0.001</scale>
            </mesh>
          </geometry>
          <max_contacts>10</max_contacts>
          <surface>
            <contact>
              <ode/>
            </contact>
            <bounce/>
            <friction>
              <torsional>
                <ode/>
              </torsional>
              <ode/>
            </friction>
          </surface>
        </collision>
        <visual name='sheet1'>
          <pose frame=''>0 0.0975 0.46 0 -0 0</pose>
          <geometry>
            <box>
              <size>0.21 0.005 0.21</size>
            </box>
          </geometry>
          <material>
            <script>
              <name>ERC_Landmark/1</name>
              <uri>__default__</uri>
            </script>
          </material>
        </visual>
        <visual name='sheet3'>
          <pose frame=''>0.0825 -0.06 0.46 0 -0 1.0472</pose>
          <geometry>
            <box>
              <size>0.21 0.005 0.21</size>
            </box>
          </geometry>
          <material>
            <script>
              <name>ERC_Landmark/1</name>
              <uri>__default__</uri>
            </script>
          </material>
        </visual>
        <visual name='sheet4'>
          <pose frame=''>-0.0775 -0.06 0.46 0 0 -1.0472</pose>
          <geometry>
            <box>
              <size>0.21 0.005 0.21</size>
            </box>
          </geometry>
          <material>
            <script>
              <name>ERC_Landmark/1</name>
              <uri>__default__</uri>
            </script>
          </material>
        </visual>
        <self_collide>0</self_collide>
        <enable_wind>0</enable_wind>
        <kinematic>0</kinematic>
      </link>
    </model>
    <model name='landmark2'>
      <pose frame=''>2 5 1.22 0 -0 1.33</pose>
      <static>1</static>
      <link name='landmark'>
        <visual name='pole_visual'>
          <pose frame=''>0 0 0.1 0 -0 0</pose>
          <geometry>
            <cylinder>
              <radius>0.01</radius>
              <length>0.4</length>
            </cylinder>
          </geometry>
          <material>
            <script>
              <name>Gazebo/Wood</name>
              <uri>__default__</uri>
            </script>
          </material>
        </visual>
        <collision name='pole_collision'>
          <pose frame=''>0 0 0.1 0 -0 0</pose>
          <geometry>
            <cylinder>
              <radius>0.01</radius>
              <length>0.4</length>
            </cylinder>
          </geometry>
          <max_contacts>10</max_contacts>
          <surface>
            <contact>
              <ode/>
            </contact>
            <bounce/>
            <friction>
              <torsional>
                <ode/>
              </torsional>
              <ode/>
            </friction>
          </surface>
        </collision>
        <visual name='box_visual'>
          <pose frame=''>0 0 0.31 0 -0 1.0472</pose>
          <geometry>
            <mesh>
              <uri>/home/baran/rover_simulation_ws/src/Simulations/blender_gazebo/sdf/meshes/ERC_Sign.stl</uri>
              <scale>0.0013 0.0013 0.001</scale>
            </mesh>
          </geometry>
          <material>
            <script>
              <name>Gazebo/White</name>
              <uri>__default__</uri>
            </script>
          </material>
        </visual>
        <collision name='box_collision'>
          <pose frame=''>0 0 0.31 0 -0 1.0472</pose>
          <geometry>
            <mesh>
              <uri>/home/baran/rover_simulation_ws/src/Simulations/blender_gazebo/sdf/meshes/ERC_Sign.stl</uri>
              <scale>0.0013 0.0013 0.001</scale>
            </mesh>
          </geometry>
          <max_contacts>10</max_contacts>
          <surface>
            <contact>
              <ode/>
            </contact>
            <bounce/>
            <friction>
              <torsional>
                <ode/>
              </torsional>
              <ode/>
            </friction>
          </surface>
        </collision>
        <visual name='sheet1'>
          <pose frame=''>0 0.0975 0.46 0 -0 0</pose>
          <geometry>
            <box>
              <size>0.21 0.005 0.21</size>
            </box>
          </geometry>
          <material>
            <script>
              <name>ERC_Landmark/2</name>
              <uri>__default__</uri>
            </script>
          </material>
        </visual>
        <visual name='sheet3'>
          <pose frame=''>0.0825 -0.06 0.46 0 -0 1.0472</pose>
          <geometry>
            <box>
              <size>0.21 0.005 0.21</size>
            </box>
          </geometry>
          <material>
            <script>
              <name>ERC_Landmark/2</name>
              <uri>__default__</uri>
            </script>
          </material>
        </visual>
        <visual name='sheet4'>
          <pose frame=''>-0.0775 -0.06 0.46 0 0 -1.0472</pose>
          <geometry>
            <box>
              <size>0.21 0.005 0.21</size>
            </box>
          </geometry>
          <material>
            <script>
              <name>ERC_Landmark/2</name>
              <uri>__default__</uri>
            </script>
          </material>
        </visual>
        <self_collide>0</self_collide>
        <enable_wind>0</enable_wind>
        <kinematic>0</kinematic>
      </link>
    </model>
    <gravity>0 0 -9.8</gravity>
    <magnetic_field>6e-06 2.3e-05 -4.2e-05</magnetic_field>
    <atmosphere type='adiabatic'/>
    <audio>
      <device>default</device>
    </audio>
    <wind/>
    <spherical_coordinates>
      <surface_model>EARTH_WGS84</surface_model>
      <latitude_deg>0</latitude_deg>
      <longitude_deg>0</longitude_deg>
      <elevation>0</elevation>
      <heading_deg>0</heading_deg>
    </spherical_coordinates>
    <model name='rover_21_description_velodyne'>
      <link name='base_link'>
        <pose frame=''>0 0 0 0 -0 0</pose>
        <inertial>
          <pose frame=''>-0.025806 -0 0.056052 0 -0 0</pose>
          <mass>8.58518</mass>
          <inertia>
            <ixx>0.181053</ixx>
            <ixy>-1.08636e-05</ixy>
            <ixz>0.0103137</ixz>
            <iyy>0.574456</iyy>
            <iyz>5.73193e-08</iyz>
            <izz>0.622524</izz>
          </inertia>
        </inertial>
        <collision name='base_link_collision'>
          <pose frame=''>0 0 0 0 -0 0</pose>
          <geometry>
            <mesh>
              <scale>1 1 1</scale>
              <uri>/home/kutaygallo/rover_sim/src/Simulations/rover_21_descriptions/rover_21_description_velodyne/meshes/base_link.STL</uri>
            </mesh>
          </geometry>
          <max_contacts>10</max_contacts>
          <surface>
            <contact>
              <ode/>
            </contact>
            <bounce/>
            <friction>
              <torsional>
                <ode/>
              </torsional>
              <ode/>
            </friction>
          </surface>
        </collision>
        <collision name='base_link_fixed_joint_lump__velodyne_collision_1'>
          <pose frame=''>0.25 0 0.15585 0 -0 0</pose>
          <geometry>
            <cylinder>
              <length>0.0717</length>
              <radius>0.0516</radius>
            </cylinder>
          </geometry>
          <surface>
            <contact>
              <ode/>
            </contact>
            <friction>
              <ode/>
              <torsional>
                <ode/>
              </torsional>
            </friction>
            <bounce/>
          </surface>
          <max_contacts>10</max_contacts>
        </collision>
        <collision name='base_link_fixed_joint_lump__camera_collision_2'>
          <pose frame=''>0.25 0 0.2 0 -0 0</pose>
          <geometry>
            <box>
              <size>0.05 0.05 0.05</size>
            </box>
          </geometry>
          <surface>
            <contact>
              <ode/>
            </contact>
            <friction>
              <ode/>
              <torsional>
                <ode/>
              </torsional>
            </friction>
            <bounce/>
          </surface>
          <max_contacts>10</max_contacts>
        </collision>
        <visual name='base_link_visual'>
          <pose frame=''>0 0 0 0 -0 0</pose>
          <geometry>
            <mesh>
              <scale>1 1 1</scale>
              <uri>/home/kutaygallo/rover_sim/src/Simulations/rover_21_descriptions/rover_21_description_velodyne/meshes/base_link.STL</uri>
            </mesh>
          </geometry>
        </visual>
        <visual name='base_link_fixed_joint_lump__velodyne_visual_1'>
          <pose frame=''>0.25 0 0.12 0 -0 0</pose>
          <geometry>
            <mesh>
              <scale>1 1 1</scale>
              <uri>/home/kutaygallo/rover_sim/src/Simulations/rover_21_descriptions/rover_21_description_velodyne/meshes/VLP16_base_1.dae</uri>
            </mesh>
          </geometry>
          <material>
            <script>
              <uri>__default__</uri>
              <name>__default__</name>
            </script>
          </material>
        </visual>
        <visual name='base_link_fixed_joint_lump__velodyne_visual_2'>
          <pose frame=''>0.25 0 0.12 0 -0 0</pose>
          <geometry>
            <mesh>
              <scale>1 1 1</scale>
              <uri>/home/kutaygallo/rover_sim/src/Simulations/rover_21_descriptions/rover_21_description_velodyne/meshes/VLP16_base_2.dae</uri>
            </mesh>
          </geometry>
          <material>
            <script>
              <uri>__default__</uri>
              <name>__default__</name>
            </script>
          </material>
        </visual>
        <visual name='base_link_fixed_joint_lump__vlp16_scan_visual_3'>
          <pose frame=''>0.25 0 0.12 0 -0 0</pose>
          <geometry>
            <mesh>
              <scale>1 1 1</scale>
              <uri>/home/kutaygallo/rover_sim/src/Simulations/rover_21_descriptions/rover_21_description_velodyne/meshes/VLP16_scan.dae</uri>
            </mesh>
          </geometry>
        </visual>
        <visual name='base_link_fixed_joint_lump__camera_visual_4'>
          <pose frame=''>0.25 0 0.2 0 -0 0</pose>
          <geometry>
            <box>
              <size>0.05 0.05 0.05</size>
            </box>
          </geometry>
          <material>
            <script>
              <uri>__default__</uri>
              <name>__default__</name>
            </script>
          </material>
        </visual>
        <velocity_decay/>
        <sensor name='vlp16_sensor' type='ray'>
          <visualize>0</visualize>
          <update_rate>10</update_rate>
          <ray>
            <scan>
              <horizontal>
                <samples>440</samples>
                <resolution>1</resolution>
                <min_angle>-2.39983</min_angle>
                <max_angle>2.39983</max_angle>
              </horizontal>
              <vertical>
                <samples>16</samples>
                <resolution>1</resolution>
                <min_angle>0</min_angle>
                <max_angle>0.261799</max_angle>
              </vertical>
            </scan>
            <range>
              <min>0.3</min>
              <max>6</max>
              <resolution>0.001</resolution>
            </range>
            <noise>
              <type>gaussian</type>
              <mean>0</mean>
              <stddev>0</stddev>
            </noise>
          </ray>
          <plugin name='gazebo_ros_laser_controller' filename='libgazebo_ros_velodyne_laser.so'>
            <topicName>/velodyne_points</topicName>
            <frameName>vlp16_scan</frameName>
            <min_range>0.5</min_range>
            <max_range>5.0</max_range>
            <gaussianNoise>0.008</gaussianNoise>
            <robotNamespace>/</robotNamespace>
          </plugin>
          <pose frame=''>0.25 0 0.12 0 -0 0</pose>
        </sensor>
        <gravity>1</gravity>
        <velocity_decay/>
        <sensor name='camera' type='camera'>
          <update_rate>30</update_rate>
          <camera name='camera'>
            <horizontal_fov>1.39626</horizontal_fov>
            <image>
              <width>800</width>
              <height>800</height>
              <format>R8G8B8</format>
            </image>
            <clip>
              <near>0.02</near>
              <far>300</far>
            </clip>
            <noise>
              <type>gaussian</type>
              <mean>0</mean>
              <stddev>0.007</stddev>
            </noise>
          </camera>
          <plugin name='camera_controller' filename='libgazebo_ros_camera.so'>
            <alwaysOn>1</alwaysOn>
            <updateRate>0.0</updateRate>
            <cameraName>/camera</cameraName>
            <imageTopicName>image</imageTopicName>
            <cameraInfoTopicName>camera_info</cameraInfoTopicName>
            <frameName>camera</frameName>
            <hackBaseline>0.07</hackBaseline>
            <distortionK1>0.0</distortionK1>
            <distortionK2>0.0</distortionK2>
            <distortionK3>0.0</distortionK3>
            <distortionT1>0.0</distortionT1>
            <distortionT2>0.0</distortionT2>
            <robotNamespace>/</robotNamespace>
          </plugin>
          <pose frame=''>0.25 0 0.2 0 -0 0</pose>
        </sensor>
        <self_collide>0</self_collide>
        <enable_wind>0</enable_wind>
        <kinematic>0</kinematic>
      </link>
      <link name='left_front_link'>
        <pose frame=''>0.353295 0.3625 -0.154225 -2.0786 0 -1.5708</pose>
        <inertial>
          <pose frame=''>-0.07551 0.000138 -4.8e-05 0 -0 0</pose>
          <mass>1.15731</mass>
          <inertia>
            <ixx>0.0178303</ixx>
            <ixy>-2.09274e-06</ixy>
            <ixz>1.42044e-06</ixz>
            <iyy>0.0096827</iyy>
            <iyz>1.80036e-06</iyz>
            <izz>0.00969344</izz>
          </inertia>
        </inertial>
        <collision name='left_front_link_collision'>
          <pose frame=''>0 0 0 0 -0 0</pose>
          <geometry>
            <mesh>
              <scale>1 1 1</scale>
              <uri>/home/kutaygallo/rover_sim/src/Simulations/rover_21_descriptions/rover_21_description_velodyne/meshes/left_front_link.STL</uri>
            </mesh>
          </geometry>
          <max_contacts>10</max_contacts>
          <surface>
            <contact>
              <ode/>
            </contact>
            <bounce/>
            <friction>
              <torsional>
                <ode/>
              </torsional>
              <ode/>
            </friction>
          </surface>
        </collision>
        <visual name='left_front_link_visual'>
          <pose frame=''>0 0 0 0 -0 0</pose>
          <geometry>
            <mesh>
              <scale>1 1 1</scale>
              <uri>/home/kutaygallo/rover_sim/src/Simulations/rover_21_descriptions/rover_21_description_velodyne/meshes/left_front_link.STL</uri>
            </mesh>
          </geometry>
        </visual>
        <self_collide>0</self_collide>
        <enable_wind>0</enable_wind>
        <kinematic>0</kinematic>
      </link>
      <joint name='left_front_joint' type='revolute'>
        <child>left_front_link</child>
        <parent>base_link</parent>
        <axis>
          <xyz>0 1 0</xyz>
          <limit>
            <lower>-1e+16</lower>
            <upper>1e+16</upper>
          </limit>
          <dynamics>
            <spring_reference>0</spring_reference>
            <spring_stiffness>0</spring_stiffness>
          </dynamics>
          <use_parent_model_frame>1</use_parent_model_frame>
        </axis>
      </joint>
      <link name='left_rear_link'>
        <pose frame=''>-0.355494 0.3625 -0.150372 1.5708 1.5332 3.14159</pose>
        <inertial>
          <pose frame=''>-2.8e-05 0.000144 0.07551 0 -0 0</pose>
          <mass>1.15731</mass>
          <inertia>
            <ixx>0.00969373</ixx>
            <ixy>2.68465e-07</ixy>
            <ixz>-1.11897e-06</ixz>
            <iyy>0.00968241</iyy>
            <iyz>2.26829e-06</iyz>
            <izz>0.0178303</izz>
          </inertia>
        </inertial>
        <collision name='left_rear_link_collision'>
          <pose frame=''>0 0 0 0 -0 0</pose>
          <geometry>
            <mesh>
              <scale>1 1 1</scale>
              <uri>/home/kutaygallo/rover_sim/src/Simulations/rover_21_descriptions/rover_21_description_velodyne/meshes/left_rear_link.STL</uri>
            </mesh>
          </geometry>
          <max_contacts>10</max_contacts>
          <surface>
            <contact>
              <ode/>
            </contact>
            <bounce/>
            <friction>
              <torsional>
                <ode/>
              </torsional>
              <ode/>
            </friction>
          </surface>
        </collision>
        <visual name='left_rear_link_visual'>
          <pose frame=''>0 0 0 0 -0 0</pose>
          <geometry>
            <mesh>
              <scale>1 1 1</scale>
              <uri>/home/kutaygallo/rover_sim/src/Simulations/rover_21_descriptions/rover_21_description_velodyne/meshes/left_rear_link.STL</uri>
            </mesh>
          </geometry>
        </visual>
        <self_collide>0</self_collide>
        <enable_wind>0</enable_wind>
        <kinematic>0</kinematic>
      </link>
      <joint name='left_rear_joint' type='revolute'>
        <child>left_rear_link</child>
        <parent>base_link</parent>
        <axis>
          <xyz>0 1 -0</xyz>
          <limit>
            <lower>-1e+16</lower>
            <upper>1e+16</upper>
          </limit>
          <dynamics>
            <spring_reference>0</spring_reference>
            <spring_stiffness>0</spring_stiffness>
          </dynamics>
          <use_parent_model_frame>1</use_parent_model_frame>
        </axis>
      </joint>
      <link name='right_front_link'>
        <pose frame=''>0.353352 -0.3625 -0.154126 -1.5708 0.966932 0</pose>
        <inertial>
          <pose frame=''>-2.8e-05 0.000144 -0.075447 0 -0 0</pose>
          <mass>1.15731</mass>
          <inertia>
            <ixx>0.00969373</ixx>
            <ixy>2.68465e-07</ixy>
            <ixz>-1.11897e-06</ixz>
            <iyy>0.00968241</iyy>
            <iyz>2.26829e-06</iyz>
            <izz>0.0178303</izz>
          </inertia>
        </inertial>
        <collision name='right_front_link_collision'>
          <pose frame=''>0 0 0 0 -0 0</pose>
          <geometry>
            <mesh>
              <scale>1 1 1</scale>
              <uri>/home/kutaygallo/rover_sim/src/Simulations/rover_21_descriptions/rover_21_description_velodyne/meshes/right_front_link.STL</uri>
            </mesh>
          </geometry>
          <max_contacts>10</max_contacts>
          <surface>
            <contact>
              <ode/>
            </contact>
            <bounce/>
            <friction>
              <torsional>
                <ode/>
              </torsional>
              <ode/>
            </friction>
          </surface>
        </collision>
        <visual name='right_front_link_visual'>
          <pose frame=''>0 0 0 0 -0 0</pose>
          <geometry>
            <mesh>
              <scale>1 1 1</scale>
              <uri>/home/kutaygallo/rover_sim/src/Simulations/rover_21_descriptions/rover_21_description_velodyne/meshes/right_front_link.STL</uri>
            </mesh>
          </geometry>
        </visual>
        <self_collide>0</self_collide>
        <enable_wind>0</enable_wind>
        <kinematic>0</kinematic>
      </link>
      <joint name='right_front_joint' type='revolute'>
        <child>right_front_link</child>
        <parent>base_link</parent>
        <axis>
          <xyz>-0 1 -0</xyz>
          <limit>
            <lower>-1e+16</lower>
            <upper>1e+16</upper>
          </limit>
          <dynamics>
            <spring_reference>0</spring_reference>
            <spring_stiffness>0</spring_stiffness>
          </dynamics>
          <use_parent_model_frame>1</use_parent_model_frame>
        </axis>
      </joint>
      <link name='right_rear_link'>
        <pose frame=''>-0.353922 -0.3625 -0.15048 -1.5708 0.8674 0</pose>
        <inertial>
          <pose frame=''>-2.8e-05 0.000144 -0.075447 0 -0 0</pose>
          <mass>1.15731</mass>
          <inertia>
            <ixx>0.00969373</ixx>
            <ixy>2.6844e-07</ixy>
            <ixz>-1.11897e-06</ixz>
            <iyy>0.00968241</iyy>
            <iyz>2.26829e-06</iyz>
            <izz>0.0178303</izz>
          </inertia>
        </inertial>
        <collision name='right_rear_link_collision'>
          <pose frame=''>0 0 0 0 -0 0</pose>
          <geometry>
            <mesh>
              <scale>1 1 1</scale>
              <uri>/home/kutaygallo/rover_sim/src/Simulations/rover_21_descriptions/rover_21_description_velodyne/meshes/right_rear_link.STL</uri>
            </mesh>
          </geometry>
          <max_contacts>10</max_contacts>
          <surface>
            <contact>
              <ode/>
            </contact>
            <bounce/>
            <friction>
              <torsional>
                <ode/>
              </torsional>
              <ode/>
            </friction>
          </surface>
        </collision>
        <visual name='right_rear_link_visual'>
          <pose frame=''>0 0 0 0 -0 0</pose>
          <geometry>
            <mesh>
              <scale>1 1 1</scale>
              <uri>/home/kutaygallo/rover_sim/src/Simulations/rover_21_descriptions/rover_21_description_velodyne/meshes/right_rear_link.STL</uri>
            </mesh>
          </geometry>
        </visual>
        <self_collide>0</self_collide>
        <enable_wind>0</enable_wind>
        <kinematic>0</kinematic>
      </link>
      <joint name='right_rear_joint' type='revolute'>
        <child>right_rear_link</child>
        <parent>base_link</parent>
        <axis>
          <xyz>-0 1 -0</xyz>
          <limit>
            <lower>-1e+16</lower>
            <upper>1e+16</upper>
          </limit>
          <dynamics>
            <spring_reference>0</spring_reference>
            <spring_stiffness>0</spring_stiffness>
          </dynamics>
          <use_parent_model_frame>1</use_parent_model_frame>
        </axis>
      </joint>
      <plugin name='gazebo_ros_control' filename='libgazebo_ros_control.so'>
        <robotSimType>gazebo_ros_control/DefaultRobotHWSim</robotSimType>
        <legacyModeNS>1</legacyModeNS>
        <robotNamespace>/</robotNamespace>
      </plugin>
      <plugin name='imu_controller' filename='libhector_gazebo_ros_imu.so'>
        <updateRate>30.0</updateRate>
        <bodyName>base_link</bodyName>
        <topicName>/imu/data</topicName>
        <accelDrift>0.005 0.005 0.005</accelDrift>
        <accelGaussianNoise>0.005 0.005 0.005</accelGaussianNoise>
        <rateDrift>0.005 0.005 0.005</rateDrift>
        <rateGaussianNoise>0.005 0.005 0.005</rateGaussianNoise>
        <headingDrift>0.005</headingDrift>
        <headingGaussianNoise>0.005</headingGaussianNoise>
        <robotNamespace>/</robotNamespace>
      </plugin>
      <static>0</static>
      <plugin name='gps_controller' filename='libhector_gazebo_ros_gps.so'>
        <updateRate>30</updateRate>
        <bodyName>base_link</bodyName>
        <frameId>base_link</frameId>
        <topicName>gps/fix</topicName>
        <velocityTopicName>navsat/vel</velocityTopicName>
        <referenceLatitude>41.1052670854</referenceLatitude>
        <referenceLongitude>29.023378124</referenceLongitude>
        <referenceHeading>0</referenceHeading>
        <referenceAltitude>0</referenceAltitude>
        <drift>0.0001 0.0001 0.0001</drift>
        <robotNamespace>/</robotNamespace>
      </plugin>
      <pose frame=''>0 0 1.8 0 -0 0</pose>
    </model>
    <model name='unit_box'>
      <pose frame=''>2.88316 -0.369545 0.5 0 -0 0</pose>
      <link name='link'>
        <inertial>
          <mass>1</mass>
          <inertia>
            <ixx>0.166667</ixx>
            <ixy>0</ixy>
            <ixz>0</ixz>
            <iyy>0.166667</iyy>
            <iyz>0</iyz>
            <izz>0.166667</izz>
          </inertia>
        </inertial>
        <collision name='collision'>
          <geometry>
            <box>
              <size>1 1 1</size>
            </box>
          </geometry>
          <max_contacts>10</max_contacts>
          <surface>
            <contact>
              <ode/>
            </contact>
            <bounce/>
            <friction>
              <torsional>
                <ode/>
              </torsional>
              <ode/>
            </friction>
          </surface>
        </collision>
        <visual name='visual'>
          <geometry>
            <box>
              <size>1 1 1</size>
            </box>
          </geometry>
          <material>
            <script>
              <name>Gazebo/Grey</name>
              <uri>file://media/materials/scripts/gazebo.material</uri>
            </script>
          </material>
        </visual>
        <self_collide>0</self_collide>
        <enable_wind>0</enable_wind>
        <kinematic>0</kinematic>
      </link>
    </model>
    <model name='unit_sphere'>
      <pose frame=''>0.353694 4.17195 0.5 0 -0 0</pose>
      <link name='link'>
        <inertial>
          <mass>1</mass>
          <inertia>
            <ixx>0.1</ixx>
            <ixy>0</ixy>
            <ixz>0</ixz>
            <iyy>0.1</iyy>
            <iyz>0</iyz>
            <izz>0.1</izz>
          </inertia>
        </inertial>
        <collision name='collision'>
          <geometry>
            <sphere>
              <radius>0.5</radius>
            </sphere>
          </geometry>
          <max_contacts>10</max_contacts>
          <surface>
            <contact>
              <ode/>
            </contact>
            <bounce/>
            <friction>
              <torsional>
                <ode/>
              </torsional>
              <ode/>
            </friction>
          </surface>
        </collision>
        <visual name='visual'>
          <geometry>
            <sphere>
              <radius>0.5</radius>
            </sphere>
          </geometry>
          <material>
            <script>
              <name>Gazebo/Grey</name>
              <uri>file://media/materials/scripts/gazebo.material</uri>
            </script>
          </material>
        </visual>
        <self_collide>0</self_collide>
        <enable_wind>0</enable_wind>
        <kinematic>0</kinematic>
      </link>
    </model>
    <model name='unit_cylinder'>
      <pose frame=''>0.552807 -3.1894 0.5 0 -0 0</pose>
      <link name='link'>
        <inertial>
          <mass>1</mass>
          <inertia>
            <ixx>0.145833</ixx>
            <ixy>0</ixy>
            <ixz>0</ixz>
            <iyy>0.145833</iyy>
            <iyz>0</iyz>
            <izz>0.125</izz>
          </inertia>
        </inertial>
        <collision name='collision'>
          <geometry>
            <cylinder>
              <radius>0.5</radius>
              <length>1</length>
            </cylinder>
          </geometry>
          <max_contacts>10</max_contacts>
          <surface>
            <contact>
              <ode/>
            </contact>
            <bounce/>
            <friction>
              <torsional>
                <ode/>
              </torsional>
              <ode/>
            </friction>
          </surface>
        </collision>
        <visual name='visual'>
          <geometry>
            <cylinder>
              <radius>0.5</radius>
              <length>1</length>
            </cylinder>
          </geometry>
          <material>
            <script>
              <name>Gazebo/Grey</name>
              <uri>file://media/materials/scripts/gazebo.material</uri>
            </script>
          </material>
        </visual>
        <self_collide>0</self_collide>
        <enable_wind>0</enable_wind>
        <kinematic>0</kinematic>
      </link>
    </model>
    <state world_name='marsyard2021'>
      <sim_time>54 66000000</sim_time>
      <real_time>76 450343588</real_time>
      <wall_time>1659451196 787121806</wall_time>
      <iterations>54066</iterations>
      <model name='Lâgari Hasan Çelebi'>
        <pose frame=''>16.8491 -1 0 0 -0 0</pose>
        <scale>1 1 1</scale>
        <link name='cosmonaut'>
          <pose frame=''>16.8491 -1 0 0 -0 0</pose>
          <velocity>0 0 0 0 -0 0</velocity>
          <acceleration>0 0 0 0 -0 0</acceleration>
          <wrench>0 0 0 0 -0 0</wrench>
        </link>
      </model>
      <model name='ground_plane'>
        <pose frame=''>0 0 0 0 -0 0</pose>
        <scale>1 1 1</scale>
        <link name='link'>
          <pose frame=''>0 0 0 0 -0 0</pose>
          <velocity>0 0 0 0 -0 0</velocity>
          <acceleration>0 0 0 0 -0 0</acceleration>
          <wrench>0 0 0 0 -0 0</wrench>
        </link>
      </model>
      <model name='landmark1'>
        <pose frame=''>3 4 1.42 0 -0 0</pose>
        <scale>1 1 1</scale>
        <link name='landmark'>
          <pose frame=''>3 4 1.42 0 -0 0</pose>
          <velocity>0 0 0 0 -0 0</velocity>
          <acceleration>0 0 0 0 -0 0</acceleration>
          <wrench>0 0 0 0 -0 0</wrench>
        </link>
      </model>
      <model name='landmark2'>
        <pose frame=''>2 5 1.22 0 -0 1.33</pose>
        <scale>1 1 1</scale>
        <link name='landmark'>
          <pose frame=''>2 5 1.22 0 -0 1.33</pose>
          <velocity>0 0 0 0 -0 0</velocity>
          <acceleration>0 0 0 0 -0 0</acceleration>
          <wrench>0 0 0 0 -0 0</wrench>
        </link>
      </model>
      <model name='rover_21_description_velodyne'>
        <pose frame=''>0.015858 -0.064845 0.304542 0.000128 -0.005653 -0.044045</pose>
        <scale>1 1 1</scale>
        <link name='base_link'>
          <pose frame=''>0.015858 -0.064845 0.304542 0.000128 -0.005653 -0.044045</pose>
          <velocity>-2.1e-05 -2e-05 0.003441 0.000261 -0.00015 -6.5e-05</velocity>
          <acceleration>-0.133504 -0.221619 6.87329 0.549642 -0.321247 -0.032685</acceleration>
          <wrench>-1.14615 -1.90264 59.0085 0 -0 0</wrench>
        </link>
        <link name='left_front_link'>
          <pose frame=''>0.385638 0.28173 0.152363 -2.14891 0.000127 -1.61485</pose>
          <velocity>1.1e-05 -1e-06 0.003557 1e-06 9.6e-05 -0.00014</velocity>
          <acceleration>-0.071916 -0.120737 7.11495 -0.0174 -0.025024 -0.18413</acceleration>
          <wrench>-0.083229 -0.139731 8.2342 0 -0 0</wrench>
        </link>
        <link name='left_rear_link'>
          <pose frame=''>-0.322474 0.312938 0.15221 1.56647 1.54167 3.09322</pose>
          <velocity>1.3e-05 3.6e-05 0.003658 -0.000217 0.000116 -0.00022</velocity>
          <acceleration>-0.057249 -0.115254 7.28002 -0.442687 -0.000301 -0.633849</acceleration>
          <wrench>-0.066255 -0.133384 8.42524 0 -0 0</wrench>
        </link>
        <link name='right_front_link'>
          <pose frame=''>0.353772 -0.44257 0.15237 -1.57058 0.959665 -0.043865</pose>
          <velocity>-1.3e-05 3.5e-05 0.003472 -0.000218 -0.000191 -0.00013</velocity>
          <acceleration>-0.07702 -0.05076 6.97673 -0.427565 -0.16763 -0.306403</acceleration>
          <wrench>-0.089136 -0.058745 8.07424 0 -0 0</wrench>
        </link>
        <link name='right_rear_link'>
          <pose frame=''>-0.352825 -0.411428 0.152016 -1.57062 0.755189 -0.043924</pose>
          <velocity>-3.1e-05 1e-06 0.003053 -9e-06 -0.000233 -3.4e-05</velocity>
          <acceleration>-0.102325 -0.186604 6.10426 -0.005987 -0.203891 0.046628</acceleration>
          <wrench>-0.118422 -0.215959 7.06452 0 -0 0</wrench>
        </link>
      </model>
      <model name='unit_box'>
        <pose frame=''>2.88293 -0.369622 0.5 0 0 -0.000228</pose>
        <scale>1 1 1</scale>
        <link name='link'>
          <pose frame=''>2.88293 -0.369622 0.5 0 0 -0.000228</pose>
          <velocity>0 0 0 0 -0 0</velocity>
          <acceleration>0 -0 0 1e-06 1e-06 0</acceleration>
          <wrench>0 -0 0 0 -0 0</wrench>
        </link>
      </model>
      <model name='unit_cylinder'>
        <pose frame=''>0.548075 -3.19369 0.499998 5e-06 5e-06 0</pose>
        <scale>1 1 1</scale>
        <link name='link'>
          <pose frame=''>0.548075 -3.19369 0.499998 5e-06 5e-06 0</pose>
          <velocity>0 0 0 0 -0 0</velocity>
          <acceleration>0 0 -9.8 0 -0 0</acceleration>
          <wrench>0 0 -9.8 0 -0 0</wrench>
        </link>
      </model>
      <model name='unit_sphere'>
        <pose frame=''>0.353694 4.17195 0.5 0 -0 0</pose>
        <scale>1 1 1</scale>
        <link name='link'>
          <pose frame=''>0.353694 4.17195 0.5 0 -0 0</pose>
          <velocity>0 0 0 0 -0 0</velocity>
          <acceleration>0 0 0 0 -0 0</acceleration>
          <wrench>0 0 0 0 -0 0</wrench>
        </link>
      </model>
      <light name='sun'>
        <pose frame=''>0 0 100 0 0.8 0</pose>
      </light>
    </state>
    <gui fullscreen='0'>
      <camera name='user_camera'>
        <pose frame=''>5 -5 2 0 0.275643 2.35619</pose>
        <view_controller>orbit</view_controller>
        <projection_type>perspective</projection_type>
      </camera>
    </gui>
  </world>
</sdf>
